<?xml version="1.0" ?>
<robot name="turtlebot3_waffle_bowl" xmlns:xacro="http://ros.org/wiki/xacro">
  <xacro:include filename="$(find turtlebot3_description)/urdf/common_properties.xacro"/>
  <xacro:include filename="$(find turtlebot3_description)/urdf/turtlebot3_waffle_bowl.gazebo.xacro"/>

  <xacro:property name="r200_cam_rgb_px" value="0.005"/>
  <xacro:property name="r200_cam_rgb_py" value="0.018"/>
  <xacro:property name="r200_cam_rgb_pz" value="0.013"/>
  <xacro:property name="r200_cam_depth_offset" value="0.01"/>

  <joint name="base_footprint_JOINT_0" type="fixed">
    <parent link="base_footprint"/>
    <child link="bowl_link"/>
    <origin rpy="0  0  0" xyz="0.17949  0.00155  0.00057"/>
    <axis xyz="0  0  0"/>
    <limit effort="0" lower="0" upper="0" velocity="0"/>
  </joint>

  <joint name="wheel_left_joint" type="revolute">
    <parent link="base_footprint"/>
    <child link="wheel_left_link"/>
    <origin rpy="-1.57  0    0" xyz="0       0.14399  0.033"/>
    <axis xyz="0  0  1"/>
    <limit effort="-1.0" lower="-1e+16" upper="1e+16" velocity="-1.0"/>
  </joint>
  <joint name="wheel_right_joint" type="revolute">
    <parent link="base_footprint"/>
    <child link="wheel_right_link"/>
    <origin rpy="-1.57  0    0" xyz="0      -0.14399  0.033"/>
    <axis xyz="0  0  1"/>
    <limit effort="-1.0" lower="-1e+16" upper="1e+16" velocity="-1.0"/>
  </joint>
  <link name="base_footprint">
    <inertial>
      <mass value="1.49691"/>
      <origin rpy="0  0  0" xyz="-0.00605  0       0.01926"/>
      <inertia ixx="0.0133097" ixy="0" ixz="0.00091065" iyy="0.0139133" iyz="0" izz="0.018379"/>
    </inertial>
    <collision name="base_footprint_fixed_joint_lump__caster_back_right_link_collision_3">
      <origin rpy="-1.57  0    0" xyz="-0.177   -0.06399  0.005"/>
      <geometry>
        <box size="0.03 0.009 0.02"/>
      </geometry>
    </collision>
    <collision name="base_footprint_fixed_joint_lump__base_scan_collision_4">
      <origin rpy="0  0  0" xyz="-0.049   0      0.1255"/>
      <geometry>
        <cylinder length="0.0315" radius="0.055"/>
      </geometry>
    </collision>
    <collision name="base_footprint_fixed_joint_lump__base_link_collision">
      <origin rpy="0  0  0" xyz="-0.064  0     0.057"/>
      <geometry>
        <box size="0.266 0.266 0.094"/>
      </geometry>
    </collision>
    <collision name="base_footprint_fixed_joint_lump__caster_back_left_link_collision_2">
      <origin rpy="-1.57  0    0" xyz="-0.177  0.064  0.005"/>
      <geometry>
        <box size="0.03 0.009 0.02"/>
      </geometry>
    </collision>
    <collision name="base_footprint_fixed_joint_lump__camera_link_collision_1">
      <origin rpy="0  0  0" xyz="0.067  0     0.111"/>
      <geometry>
        <box size="0.012 0.132 0.02"/>
      </geometry>
    </collision>
    <visual name="base_footprint_fixed_joint_lump__base_scan_visual_2">
      <origin rpy="0  0  0" xyz="-0.064  0     0.132"/>
      <geometry>
        <mesh filename="package://turtlebot3_description/meshes/sensors/lds.stl" scale="0.001 0.001 0.001"/>
      </geometry>
    </visual>
    <visual name="base_footprint_fixed_joint_lump__camera_link_visual_1">
      <origin rpy="1.57  0    1.57" xyz="0.064 -0.065  0.104"/>
      <geometry>
        <mesh filename="package://turtlebot3_description/meshes/sensors/r200.dae" scale="1 1 1"/>
      </geometry>
    </visual>
    <visual name="base_footprint_fixed_joint_lump__base_link_visual">
      <origin rpy="0  0  0" xyz="-0.064  0     0.01"/>
      <geometry>
        <mesh filename="package://turtlebot3_description/meshes/wheels/waffle_base.stl" scale="0.001 0.001 0.001"/>
      </geometry>
    </visual>
  </link>
  <link name="wheel_left_link">
    <inertial>
      <mass value="0.0284989"/>
      <origin rpy="0  0  0" xyz="0  0  0"/>
      <inertia ixx="1.11756e-05" ixy="-4.23698e-11" ixz="-5.93817e-09" iyy="1.11924e-05" iyz="-1.44001e-11" izz="2.07126e-05"/>
    </inertial>
    <collision name="wheel_left_link_collision">
      <origin rpy="0  0  0" xyz="0  0  0"/>
      <geometry>
        <cylinder length="0.018" radius="0.033"/>
      </geometry>
    </collision>
    <visual name="wheel_left_link_visual">
      <origin rpy="1.57  0    0" xyz="0  0  0"/>
      <geometry>
        <mesh filename="package://turtlebot3_description/meshes/wheels/left_tire.stl" scale="0.001 0.001 0.001"/>
      </geometry>
    </visual>
  </link>
  <link name="wheel_right_link">
    <inertial>
      <mass value="0.0284989"/>
      <origin rpy="0  0  0" xyz="0  0  0"/>
      <inertia ixx="1.11756e-05" ixy="-4.23698e-11" ixz="-5.93817e-09" iyy="1.11924e-05" iyz="-1.44001e-11" izz="2.07126e-05"/>
    </inertial>
    <collision name="wheel_right_link_collision">
      <origin rpy="0  0  0" xyz="0  0  0"/>
      <geometry>
        <cylinder length="0.018" radius="0.033"/>
      </geometry>
    </collision>
    <visual name="wheel_right_link_visual">
      <origin rpy="1.57  0    0" xyz="0  0  0"/>
      <geometry>
        <mesh filename="package://turtlebot3_description/meshes/wheels/right_tire.stl" scale="0.001 0.001 0.001"/>
      </geometry>
    </visual>
  </link>
  <link name="bowl_link">
    <inertial>
      <mass value="0.1"/>
      <origin rpy="0  0  0" xyz="0      0      0.0175"/>
      <inertia ixx="0.000250308" ixy="0" ixz="0" iyy="0.000250308" iyz="0" izz="0.0004802"/>
    </inertial>
    <collision name="collision">
      <origin rpy="0  0  0" xyz="0      0      0.0175"/>
      <geometry>
        <cylinder length="0.035" radius="0.098"/>
      </geometry>
    </collision>
    <visual name="visual">
      <origin rpy="0  0  0" xyz="0  0  0"/>
      <geometry>
        <mesh filename="model://bowl/meshes/bowl.dae" scale="1.0 1.0 1.0"/>
      </geometry>
    </visual>
  </link>
</robot>
